Workbook

Sheet Overview
A1: Discover Lebanon - Zone 2: Keserwan & Jbeil
A2: Jounieh - Harissa - Faraya - Byblos - Aqoura | Public evidence checked 2026-09-10
A4: Scope | B4: Restaurants, coffee shops, bars and bakeries, plus activities and visitable places: heritage, museums, nature, snow sports, adventure, beaches and festivals. | D4: KPI | E4: Value | G4: Area | H4: Food | I4: Activities
A5: Geographic rule | B5: Every record carries an Exact Locality. Kaslik, Zouk Mosbeh, Ghazir, Amchit, Annaya, Faqra and Mzaar are never silently merged into a city name. | D5: Areas researched | E5: 5 | G5: Jounieh | H5: =COUNTIF('Food & Drink'!$B$2:$B$259,G5) -> 102 | I5: =COUNTIF(Activities!$B$2:$B$59,G5) -> 14
A6: Harissa rule | B6: Harissa is treated as its own area even though it sits administratively above Jounieh, because its venues serve the shrine and the cable car. | D6: Food & drink records | E6: =COUNTA('Food & Drink'!D2:D259) -> 258 | G6: Harissa | H6: =COUNTIF('Food & Drink'!$B$2:$B$259,G6) -> 27 | I6: =COUNTIF(Activities!$B$2:$B$59,G6) -> 4
A7: Aqoura rule | B7: Aqoura is a high-mountain destination with thin commercial coverage. Few dining records is a finding, not a gap. | D7: Activity records | E7: =COUNTA(Activities!D2:D59) -> 58 | G7: Faraya | H7: =COUNTIF('Food & Drink'!$B$2:$B$259,G7) -> 41 | I7: =COUNTIF(Activities!$B$2:$B$59,G7) -> 12
A8: Evidence rule | B8: Ratings and review counts are only recorded where a public review platform actually publishes them. Blank means unknown, never estimated. | D8: Localities represented | E8: =SUMPRODUCT((COUNTIF('Food & Drink'!C2:C259,'Food & Drink'!C2:C259)>0)/COUNTIF('Food & Drink'!C2:C259,'Food & Drink'!C2:C259)) -> 29 | G8: Byblos | H8: =COUNTIF('Food & Drink'!$B$2:$B$259,G8) -> 81 | I8: =COUNTIF(Activities!$B$2:$B$59,G8) -> 20
A9: Confidence | B9: High = review-platform data or a well-established venue. Medium = current directory listing. Low = listing exists but is thin; verify before relying on it. | D9: Records with public rating | E9: =COUNT('Food & Drink'!G2:G259)+COUNT(Activities!F2:F59) -> 70 | G9: Aqoura | H9: =COUNTIF('Food & Drink'!$B$2:$B$259,G9) -> 7 | I9: =COUNTIF(Activities!$B$2:$B$59,G9) -> 8
D10: High-confidence records | E10: =COUNTIF('Food & Drink'!I2:I259,"High")+COUNTIF(Activities!I2:I59,"High") -> 88

Sheet Area Summary
A1: Area | B1: Geographic Scope | C1: Food Records | D1: Activity Records | E1: High Confidence | F1: Rated Venues | G1: Localities | H1: Research Note
A2: Jounieh | B2: Jounieh bay city + Kaslik, Sarba, Maameltein, Haret Sakher, Zouk Mosbeh, Ghazir, Adma, Kfarhbab | C2: =COUNTIF('Food & Drink'!$B$2:$B$259,$A2) -> 102 | D2: =COUNTIF(Activities!$B$2:$B$59,$A2) -> 14 | E2: =COUNTIFS('Food & Drink'!$B$2:$B$259,$A2,'Food & Drink'!$I$2:$I$259,"High")+COUNTIFS(Activities!$B$2:$B$59,$A2,Activities!$I$2:$I$59,"High") -> 32 | F2: =COUNTIFS('Food & Drink'!$B$2:$B$259,$A2,'Food & Drink'!$G$2:$G$259,">0") -> 9 | G2: 14 | H2: Coastal Keserwan. Exact Locality separates Jounieh city proper from the Kaslik/Zouk university strip and the Ghazir hillside.
A3: Harissa | B3: Harissa - Daraoun pilgrimage plateau above Jounieh | C3: =COUNTIF('Food & Drink'!$B$2:$B$259,$A3) -> 27 | D3: =COUNTIF(Activities!$B$2:$B$59,$A3) -> 4 | E3: =COUNTIFS('Food & Drink'!$B$2:$B$259,$A3,'Food & Drink'!$I$2:$I$259,"High")+COUNTIFS(Activities!$B$2:$B$59,$A3,Activities!$I$2:$I$59,"High") -> 6 | F3: =COUNTIFS('Food & Drink'!$B$2:$B$259,$A3,'Food & Drink'!$G$2:$G$259,">0") -> 1 | G3: 2 | H3: Small plateau; almost every venue is tied to the shrine, the teleferique station or the ridge viewpoints.
A4: Faraya | B4: Kfardebian municipality: Faraya village, Faqra, Mzaar ski area | C4: =COUNTIF('Food & Drink'!$B$2:$B$259,$A4) -> 41 | D4: =COUNTIF(Activities!$B$2:$B$59,$A4) -> 12 | E4: =COUNTIFS('Food & Drink'!$B$2:$B$259,$A4,'Food & Drink'!$I$2:$I$259,"High")+COUNTIFS(Activities!$B$2:$B$59,$A4,Activities!$I$2:$I$59,"High") -> 11 | F4: =COUNTIFS('Food & Drink'!$B$2:$B$259,$A4,'Food & Drink'!$G$2:$G$259,">0") -> 10 | G4: 4 | H4: Faraya is the common name; Kfardebian is the administrative one. Faqra and Mzaar are kept as separate localities.
A5: Byblos | B5: Byblos/Jbeil city, old port and souk, Byblos Sud, plus Amchit and Annaya | C5: =COUNTIF('Food & Drink'!$B$2:$B$259,$A5) -> 81 | D5: =COUNTIF(Activities!$B$2:$B$59,$A5) -> 20 | E5: =COUNTIFS('Food & Drink'!$B$2:$B$259,$A5,'Food & Drink'!$I$2:$I$259,"High")+COUNTIFS(Activities!$B$2:$B$59,$A5,Activities!$I$2:$I$59,"High") -> 35 | F5: =COUNTIFS('Food & Drink'!$B$2:$B$259,$A5,'Food & Drink'!$G$2:$G$259,">0") -> 16 | G5: 15 | H5: Byblos city core is UNESCO-listed. Amchit and Annaya are neighbouring towns, never merged into 'Byblos city'.
A6: Aqoura | B6: Aaqoura village, Afqa, upper Adonis (Nahr Ibrahim) valley, Laqlouq approach | C6: =COUNTIF('Food & Drink'!$B$2:$B$259,$A6) -> 7 | D6: =COUNTIF(Activities!$B$2:$B$59,$A6) -> 8 | E6: =COUNTIFS('Food & Drink'!$B$2:$B$259,$A6,'Food & Drink'!$I$2:$I$259,"High")+COUNTIFS(Activities!$B$2:$B$59,$A6,Activities!$I$2:$I$59,"High") -> 4 | F6: =COUNTIFS('Food & Drink'!$B$2:$B$259,$A6,'Food & Drink'!$G$2:$G$259,">0") -> 1 | G6: 5 | H6: High-mountain Jbeil district. Thin commercial coverage by design - this is a nature and heritage destination.

Sheet Food & Drink
A1: ID | B1: Area | C1: Exact Locality | D1: Venue Name | E1: Type / Cuisine | F1: Status | G1: Rating | H1: Reviews | I1: Confidence | J1: Evidence | K1: Source URL | L1: Map / Search Link | M1: Notes | N1: Last Checked
A2: 1 | B2: Byblos | C2: Byblos city / old port | D2: Malena | E2: Lebanese - Seafood | F2: Open | G2: 4.7 | H2: 512 | I2: High | J2: Review-rated listing | K2: https://www.tripadvisor.com/Restaurants-g298264-Byblos_Mount_Lebanon_Governorate.html | L2: https://www.google.com/maps/search/?api=1&query=Malena%2C+Byblos+city+%2F+old+port%2C+Lebanon | M2: Garden restaurant at the old port; Lebanese-Italian crossover, the highest-reviewed table in town. | N2: 2026-09-10
A3: 2 | B3: Byblos | C3: Byblos city | D3: Feniqia | E3: Lebanese - Mediterranean | F3: Open | G3: 4.5 | H3: 674 | I3: High | J3: Review-rated listing | K3: https://www.tripadvisor.com/Restaurants-g298264-Byblos_Mount_Lebanon_Governorate.html | L3: https://www.google.com/maps/search/?api=1&query=Feniqia%2C+Byblos+city%2C+Lebanon | M3: Largest review base in Byblos; classic mezze and grills. | N3: 2026-09-10
A4: 3 | B4: Byblos | C4: Mina Jbeil (old port) | D4: Bab El-Mina | E4: Lebanese - Seafood | F4: Open | G4: 4 | H4: 240 | I4: High | J4: Review-rated listing | K4: https://www.tripadvisor.com/Restaurants-g298264-Byblos_Mount_Lebanon_Governorate.html | L4: https://www.google.com/maps/search/?api=1&query=Bab+El-Mina%2C+Mina+Jbeil+%28old+port%29%2C+Lebanon | M4: Port-front institution; catch-of-the-day fish beside the crusader castle. | N4: 2026-09-10
A5: 4 | B5: Byblos | C5: Byblos city / seafront | D5: Babel sur Mer | E5: Lebanese - Seafood | F5: Open | G5: 4.2 | H5: 41 | I5: High | J5: Review-rated listing | K5: https://www.tripadvisor.com/Restaurants-g298264-Byblos_Mount_Lebanon_Governorate.html | L5: https://www.google.com/maps/search/?api=1&query=Babel+sur+Mer%2C+Byblos+city+%2F+seafront%2C+Lebanon | M5: Sea-facing branch of the Babel group. | N5: 2026-09-10
A6: 5 | B6: Byblos | C6: Byblos city | D6: Haven - The Cabin | E6: Cafe - Bar | F6: Open | G6: 4.8 | H6: 30 | I6: High | J6: Review-rated listing | K6: https://www.tripadvisor.com/Restaurants-g298264-c8-Byblos_Mount_Lebanon_Governorate.html | L6: https://www.google.com/maps/search/?api=1&query=Haven+-+The+Cabin%2C+Byblos+city%2C+Lebanon | M6: Highest-rated cafe in Byblos; coffee, salads and a wide view. | N6: 2026-09-10
A7: 6 | B7: Byblos | C7: Pepe Abed Street | D7: Locanda - A la Granda | E7: Lebanese - International | F7: Open | G7: 4.3 | H7: 291 | I7: High | J7: Review-rated listing | K7: https://www.tripadvisor.com/Restaurants-g298264-Byblos_Mount_Lebanon_Governorate.html | L7: https://www.google.com/maps/search/?api=1&query=Locanda+-+A+la+Granda%2C+Pepe+Abed+Street%2C+Lebanon | M7: Balcony tables over the old town; fusion menu. | N7: 2026-09-10
A8: 7 | B8: Byblos | C8: Byblos city | D8: Kami | E8: Japanese - Seafood | F8: Open | G8: 4.7 | H8: 202 | I8: High | J8: Review-rated listing | K8: https://www.tripadvisor.com/Restaurants-g298264-Byblos_Mount_Lebanon_Governorate.html | L8: https://www.google.com/maps/search/?api=1&query=Kami%2C+Byblos+city%2C+Lebanon | M8: Sushi and sashimi; the strongest Japanese kitchen in the zone. | N8: 2026-09-10
A9: 8 | B9: Byblos | C9: Byblos city / seafront | D9: Aal Baher | E9: Lebanese - Seafood | F9: Open | G9: 4.1 | H9: 78 | I9: High | J9: Review-rated listing | K9: https://www.tripadvisor.com/Restaurants-g298264-Byblos_Mount_Lebanon_Governorate.html | L9: https://www.google.com/maps/search/?api=1&query=Aal+Baher%2C+Byblos+city+%2F+seafront%2C+Lebanon | M9: Straightforward seafront fish house. | N9: 2026-09-10
A10: 9 | B10: Byblos | C10: Annaya | D10: Kanater Annaya Restaurant | E10: Lebanese - Mediterranean | F10: Open | G10: 4.9 | H10: 74 | I10: High | J10: Review-rated listing | K10: https://www.tripadvisor.com/Restaurants-g298264-Byblos_Mount_Lebanon_Governorate.html | L10: https://www.google.com/maps/search/?api=1&query=Kanater+Annaya+Restaurant%2C+Annaya%2C+Lebanon | M10: Highest-rated table in the area; on the pilgrimage road to St Charbel. | N10: 2026-09-10
A11: 10 | B11: Byblos | C11: Mina Jbeil (old port) | D11: Chez Pepe (Pepe Abed) | E11: Lebanese - Seafood | F11: Open | G11: 3.9 | H11: 256 | I11: High | J11: Review-rated listing | K11: https://www.tripadvisor.com/Restaurants-g298264-Byblos_Mount_Lebanon_Governorate.html | L11: https://www.google.com/maps/search/?api=1&query=Chez+Pepe+%28Pepe+Abed%29%2C+Mina+Jbeil+%28old+port%29%2C+Lebanon | M11: The historic fishing-club restaurant; more landmark than fine dining. | N11: 2026-09-10
A12: 11 | B12: Byblos | C12: Byblos city | D12: Sapori E Vini | E12: Italian | F12: Open | G12: 4.5 | I12: High | J12: Review-rated listing | K12: https://www.tripadvisor.com/Restaurants-g298264-Byblos_Mount_Lebanon_Governorate.html | L12: https://www.google.com/maps/search/?api=1&query=Sapori+E+Vini%2C+Byblos+city%2C+Lebanon | M12: Italian kitchen and wine list. | N12: 2026-09-10
A13: 12 | B13: Byblos | C13: Byblos city | D13: Adonai Le Petit Libanais | E13: Lebanese | F13: Open | G13: 4.6 | I13: High | J13: Review-rated listing | K13: https://www.tripadvisor.com/Restaurants-g298264-Byblos_Mount_Lebanon_Governorate.html | L13: https://www.google.com/maps/search/?api=1&query=Adonai+Le+Petit+Libanais%2C+Byblos+city%2C+Lebanon | M13: Small traditional Lebanese room. | N13: 2026-09-10
A14: 13 | B14: Byblos | C14: Byblos city | D14: Mon Maki A Moi | E14: Japanese - Sushi | F14: Open | G14: 4.1 | I14: High | J14: Review-rated listing | K14: https://www.tripadvisor.com/Restaurants-g298264-Byblos_Mount_Lebanon_Governorate.html | L14: https://www.google.com/maps/search/?api=1&query=Mon+Maki+A+Moi%2C+Byblos+city%2C+Lebanon | M14: Sushi bar. | N14: 2026-09-10
A15: 14 | B15: Byblos | C15: Roman Sea Road | D15: Malak Al Baher | E15: Seafood | F15: Open | I15: Medium | J15: Current city dining guide | K15: https://artandthensome.com/best-restaurants-in-jbeil/ | L15: https://www.google.com/maps/search/?api=1&query=Malak+Al+Baher%2C+Roman+Sea+Road%2C+Lebanon | M15: Stone house by the sea; daily catch and garden seating. | N15: 2026-09-10
A16: 15 | B16: Byblos | C16: Byblos Sud | D16: Grecco | E16: Greek - Mediterranean | F16: Open | I16: Medium | J16: Current city dining guide | K16: https://artandthensome.com/best-restaurants-in-jbeil/ | L16: https://www.google.com/maps/search/?api=1&query=Grecco%2C+Byblos+Sud%2C+Lebanon | M16: Whitewashed seaside Greek; grilled fish and salads. | N16: 2026-09-10
A17: 16 | B17: Byblos | C17: Byblos city | D17: Un Petit Gato | E17: Bakery - French patisserie | F17: Open | G17: 5 | H17: 3 | I17: Medium | J17: Review-rated listing | K17: https://www.tripadvisor.com/Restaurants-g298264-c8-Byblos_Mount_Lebanon_Governorate.html | L17: https://www.google.com/maps/search/?api=1&query=Un+Petit+Gato%2C+Byblos+city%2C+Lebanon | M17: Dessert boutique. | N17: 2026-09-10
A18: 17 | B18: Byblos | C18: Byblos city | D18: NewYorker Cup | E18: Coffee & Tea | F18: Open | G18: 4.3 | H18: 3 | I18: Medium | J18: Review-rated listing | K18: https://www.tripadvisor.com/Restaurants-g298264-c8-Byblos_Mount_Lebanon_Governorate.html | L18: https://www.google.com/maps/search/?api=1&query=NewYorker+Cup%2C+Byblos+city%2C+Lebanon | M18: Neighbourhood coffee bar. | N18: 2026-09-10
A19: 18 | B19: Byblos | C19: Byblos city | D19: Bint El Chalabiya | E19: Lebanese - Cafe | F19: Open | G19: 3 | H19: 1 | I19: Medium | J19: Review-rated listing | K19: https://www.tripadvisor.com/Restaurants-g298264-c8-Byblos_Mount_Lebanon_Governorate.html | L19: https://www.google.com/maps/search/?api=1&query=Bint+El+Chalabiya%2C+Byblos+city%2C+Lebanon | M19: Lebanese cafe-restaurant. | N19: 2026-09-10
A20: 19 | B20: Byblos | C20: Byblos city / seafront | D20: Mhanna Sur Mer | E20: Restaurant | F20: Open | I20: Medium | J20: Local directory listing | K20: https://wenrayhin.com/en/towns/byblos/food_drink | L20: https://www.google.com/maps/search/?api=1&query=Mhanna+Sur+Mer%2C+Byblos+city+%2F+seafront%2C+Lebanon | N20: 2026-09-10
A21: 20 | B21: Byblos | C21: Byblos city | D21: Black Barn | E21: Restaurant | F21: Open | I21: Medium | J21: Local directory listing | K21: https://wenrayhin.com/en/towns/byblos/food_drink | L21: https://www.google.com/maps/search/?api=1&query=Black+Barn%2C+Byblos+city%2C+Lebanon | N21: 2026-09-10
A22: 21 | B22: Byblos | C22: Byblos city | D22: BDP Beach | E22: Beach restaurant | F22: Open | I22: Medium | J22: Local directory listing | K22: https://wenrayhin.com/en/towns/byblos/food_drink | L22: https://www.google.com/maps/search/?api=1&query=BDP+Beach%2C+Byblos+city%2C+Lebanon | M22: Seasonal beach venue - verify opening months. | N22: 2026-09-10
A23: 22 | B23: Byblos | C23: Byblos city | D23: Byblos Fun Planet | E23: Family restaurant | F23: Open | I23: Medium | J23: Local directory listing | K23: https://wenrayhin.com/en/towns/byblos/food_drink | L23: https://www.google.com/maps/search/?api=1&query=Byblos+Fun+Planet%2C+Byblos+city%2C+Lebanon | M23: Doubles as a family entertainment venue. | N23: 2026-09-10
A24: 23 | B24: Byblos | C24: Byblos city | D24: Roadster Diner | E24: American diner - chain | F24: Open | I24: High | J24: Local directory listing | K24: https://wenrayhin.com/en/towns/byblos/food_drink | L24: https://www.google.com/maps/search/?api=1&query=Roadster+Diner%2C+Byblos+city%2C+Lebanon | N24: 2026-09-10
A25: 24 | B25: Byblos | C25: Byblos city | D25: Babel Bahr | E25: Lebanese - Seafood | F25: Open | I25: Medium | J25: Local directory listing | K25: https://wenrayhin.com/en/towns/byblos/food_drink | L25: https://www.google.com/maps/search/?api=1&query=Babel+Bahr%2C+Byblos+city%2C+Lebanon | N25: 2026-09-10
A26: 25 | B26: Byblos | C26: Byblos city | D26: El Molino | E26: Restaurant | F26: Open | I26: Medium | J26: Local directory listing | K26: https://wenrayhin.com/en/towns/byblos/food_drink | L26: https://www.google.com/maps/search/?api=1&query=El+Molino%2C+Byblos+city%2C+Lebanon | N26: 2026-09-10
A27: 26 | B27: Byblos | C27: Byblos city | D27: MuN | E27: Restaurant | F27: Open | I27: Medium | J27: Local directory listing | K27: https://wenrayhin.com/en/towns/byblos/food_drink | L27: https://www.google.com/maps/search/?api=1&query=MuN%2C+Byblos+city%2C+Lebanon | N27: 2026-09-10
A28: 27 | B28: Byblos | C28: Byblos city | D28: Stephano | E28: Restaurant | F28: Open | I28: Medium | J28: Local directory listing | K28: https://wenrayhin.com/en/towns/byblos/food_drink | L28: https://www.google.com/maps/search/?api=1&query=Stephano%2C+Byblos+city%2C+Lebanon | N28: 2026-09-10
A29: 28 | B29: Byblos | C29: Byblos city | D29: Se | E29: Restaurant | F29: Open | I29: Low | J29: Local directory listing | K29: https://wenrayhin.com/en/towns/byblos/food_drink | L29: https://www.google.com/maps/search/?api=1&query=Se%2C+Byblos+city%2C+Lebanon | M29: Short name - confirm exact branding on site. | N29: 2026-09-10
A30: 29 | B30: Byblos | C30: Byblos city | D30: Brouhaha Intown | E30: Restaurant | F30: Open | I30: Medium | J30: Local directory listing | K30: https://wenrayhin.com/en/towns/byblos/food_drink | L30: https://www.google.com/maps/search/?api=1&query=Brouhaha+Intown%2C+Byblos+city%2C+Lebanon | N30: 2026-09-10
A31: 30 | B31: Byblos | C31: Byblos city | D31: Beit Nazha | E31: Traditional Lebanese | F31: Open | I31: Medium | J31: Local directory listing | K31: https://wenrayhin.com/en/towns/byblos/food_drink | L31: https://www.google.com/maps/search/?api=1&query=Beit+Nazha%2C+Byblos+city%2C+Lebanon | N31: 2026-09-10
A32: 31 | B32: Byblos | C32: Byblos city | D32: e Baladi | E32: Traditional Lebanese | F32: Open | I32: Medium | J32: Local directory listing | K32: https://wenrayhin.com/en/towns/byblos/food_drink | L32: https://www.google.com/maps/search/?api=1&query=e+Baladi%2C+Byblos+city%2C+Lebanon | N32: 2026-09-10
A33: 32 | B33: Byblos | C33: Byblos city | D33: Ksar Lebanese Diner | E33: Traditional Lebanese | F33: Open | I33: Medium | J33: Local directory listing | K33: https://wenrayhin.com/en/towns/byblos/food_drink | L33: https://www.google.com/maps/search/?api=1&query=Ksar+Lebanese+Diner%2C+Byblos+city%2C+Lebanon | N33: 2026-09-10
A34: 33 | B34: Byblos | C34: Byblos souk | D34: Malak Al Tawouk | E34: Street food - chicken | F34: Open | I34: High | J34: Local directory listing | K34: https://wenrayhin.com/en/towns/byblos/food_drink | L34: https://www.google.com/maps/search/?api=1&query=Malak+Al+Tawouk%2C+Byblos+souk%2C+Lebanon | N34: 2026-09-10
A35: 34 | B35: Byblos | C35: Byblos city | D35: Zaatar w Zeit | E35: Street food - chain | F35: Open | I35: High | J35: Local directory listing | K35: https://wenrayhin.com/en/towns/byblos/food_drink | L35: https://www.google.com/maps/search/?api=1&query=Zaatar+w+Zeit%2C+Byblos+city%2C+Lebanon | N35: 2026-09-10
A36: 35 | B36: Byblos | C36: Byblos city | D36: Four Guys London | E36: Street food - burgers | F36: Open | I36: Medium | J36: Local directory listing | K36: https://wenrayhin.com/en/towns/byblos/food_drink | L36: https://www.google.com/maps/search/?api=1&query=Four+Guys+London%2C+Byblos+city%2C+Lebanon | N36: 2026-09-10
A37: 36 | B37: Byblos | C37: Byblos city | D37: Richeese | E37: Street food - chain | F37: Open | I37: Medium | J37: Local directory listing | K37: https://wenrayhin.com/en/towns/byblos/food_drink | L37: https://www.google.com/maps/search/?api=1&query=Richeese%2C+Byblos+city%2C+Lebanon | N37: 2026-09-10
A38: 37 | B38: Byblos | C38: Byblos city | D38: Burger King | E38: Street food - chain | F38: Open | I38: High | J38: Local directory listing | K38: https://wenrayhin.com/en/towns/byblos/food_drink | L38: https://www.google.com/maps/search/?api=1&query=Burger+King%2C+Byblos+city%2C+Lebanon | N38: 2026-09-10
A39: 38 | B39: Byblos | C39: Byblos city | D39: Bachir Ice Cream | E39: Dessert | F39: Open | I39: High | J39: Local directory listing | K39: https://wenrayhin.com/en/towns/byblos/food_drink | L39: https://www.google.com/maps/search/?api=1&query=Bachir+Ice+Cream%2C+Byblos+city%2C+Lebanon | N39: 2026-09-10
A40: 39 | B40: Byblos | C40: Byblos city | D40: Wooden Bakery | E40: Bakery - chain | F40: Open | I40: High | J40: Local directory listing | K40: https://wenrayhin.com/en/towns/byblos/food_drink | L40: https://www.google.com/maps/search/?api=1&query=Wooden+Bakery%2C+Byblos+city%2C+Lebanon | N40: 2026-09-10
...

Sheet Activities
A1: ID | B1: Area | C1: Exact Locality | D1: Activity / Place | E1: Category | F1: Rating | G1: Reviews | H1: What You Can Do | I1: Confidence | J1: Season | K1: Source URL | L1: Map / Search Link | M1: Notes | N1: Last Checked
A2: 1 | B2: Byblos | C2: Byblos city | D2: Byblos Castle | E2: Heritage - Castle | F2: 4.5 | G2: 681 | H2: Walk the 12th-century Crusader keep and the archaeological site below it | I2: High | J2: Year-round | K2: https://www.tripadvisor.com/Attractions-g298264-Activities-Byblos_Mount_Lebanon_Governorate.html | L2: https://www.google.com/maps/search/?api=1&query=Byblos+Castle%2C+Byblos+city%2C+Lebanon | M2: The anchor sight of the zone; the ticket covers the whole excavation field. | N2: 2026-09-10
A3: 2 | B3: Byblos | C3: Byblos city | D3: Memory of Time | E3: Museum - Specialty | F3: 4.9 | G3: 551 | H3: See one of the world's largest fossil-fish collections, quarried in Mount Lebanon | I3: High | J3: Year-round | K3: https://www.tripadvisor.com/Attractions-g298264-Activities-Byblos_Mount_Lebanon_Governorate.html | L3: https://www.google.com/maps/search/?api=1&query=Memory+of+Time%2C+Byblos+city%2C+Lebanon | M3: Highest-rated attraction in the entire zone. | N3: 2026-09-10
A4: 3 | B4: Byblos | C4: Byblos city | D4: Old Souk | E4: Heritage - Souk | F4: 4.3 | G4: 594 | H4: Wander the restored medieval lanes, shop crafts, eat and drink | I4: High | J4: Year-round | K4: https://www.tripadvisor.com/Attractions-g298264-Activities-Byblos_Mount_Lebanon_Governorate.html | L4: https://www.google.com/maps/search/?api=1&query=Old+Souk%2C+Byblos+city%2C+Lebanon | M4: Busiest in the evening; free to walk. | N4: 2026-09-10
A5: 4 | B5: Byblos | C5: Byblos city | D5: Byblos Port | E5: Heritage - Historic harbour | F5: 4.5 | G5: 17 | H5: Photograph the Phoenician harbour, take a short boat run | I5: High | J5: Year-round | K5: https://www.tripadvisor.com/Attractions-g298264-Activities-Byblos_Mount_Lebanon_Governorate.html | L5: https://www.google.com/maps/search/?api=1&query=Byblos+Port%2C+Byblos+city%2C+Lebanon | N5: 2026-09-10
A6: 5 | B6: Byblos | C6: Byblos city | D6: Saint John-Marc Cathedral | E6: Heritage - Religious | F6: 4.6 | G6: 57 | H6: Visit the 12th-century Romanesque crusader church | I6: High | J6: Year-round | K6: https://www.tripadvisor.com/Attractions-g298264-Activities-Byblos_Mount_Lebanon_Governorate.html | L6: https://www.google.com/maps/search/?api=1&query=Saint+John-Marc+Cathedral%2C+Byblos+city%2C+Lebanon | N6: 2026-09-10
A7: 6 | B7: Byblos | C7: Annaya | D7: Monastery of St Maron, Annaya | E7: Heritage - Pilgrimage | F7: 4.7 | G7: 65 | H7: Visit the shrine and hermitage of Saint Charbel | I7: High | J7: Year-round | K7: https://www.tripadvisor.com/Attractions-g298264-Activities-Byblos_Mount_Lebanon_Governorate.html | L7: https://www.google.com/maps/search/?api=1&query=Monastery+of+St+Maron%2C+Annaya%2C+Annaya%2C+Lebanon | M7: Lebanon's most visited pilgrimage site after Harissa. | N7: 2026-09-10
A8: 7 | B8: Byblos | C8: Byblos city | D8: Modern and Contemporary Art Museum | E8: Museum - Art | F8: 5 | G8: 22 | H8: See Lebanese modern and contemporary collections | I8: High | J8: Year-round | K8: https://www.tripadvisor.com/Attractions-g298264-Activities-Byblos_Mount_Lebanon_Governorate.html | L8: https://www.google.com/maps/search/?api=1&query=Modern+and+Contemporary+Art+Museum%2C+Byblos+city%2C+Lebanon | N8: 2026-09-10
A9: 8 | B9: Byblos | C9: Byblos city | D9: Armenian Genocide Orphans' Museum | E9: Museum - History | F9: 5 | G9: 12 | H9: Visit the 'Aram Bezikian' museum on the orphanage site | I9: High | J9: Year-round | K9: https://www.tripadvisor.com/Attractions-g298264-Activities-Byblos_Mount_Lebanon_Governorate.html | L9: https://www.google.com/maps/search/?api=1&query=Armenian+Genocide+Orphans%27+Museum%2C+Byblos+city%2C+Lebanon | N9: 2026-09-10
A10: 9 | B10: Byblos | C10: Byblos city | D10: Vero Museum | E10: Museum - Specialty | F10: 5 | G10: 6 | H10: Tour the private collection museum | I10: Medium | J10: Year-round | K10: https://www.tripadvisor.com/Attractions-g298264-Activities-Byblos_Mount_Lebanon_Governorate.html | L10: https://www.google.com/maps/search/?api=1&query=Vero+Museum%2C+Byblos+city%2C+Lebanon | N10: 2026-09-10
A11: 10 | B11: Byblos | C11: Hakel | D11: Expo Hakel | E11: Museum - Natural history | F11: 5 | G11: 3 | H11: See Cretaceous fossil beds and the on-site collection | I11: Medium | J11: Year-round | K11: https://www.tripadvisor.com/Attractions-g298264-Activities-Byblos_Mount_Lebanon_Governorate.html | L11: https://www.google.com/maps/search/?api=1&query=Expo+Hakel%2C+Hakel%2C+Lebanon | M11: Outside Byblos city - check access before driving. | N11: 2026-09-10
A12: 11 | B12: Byblos | C12: Byblos city | D12: Byblos Wax Museum | E12: Museum - Specialty | F12: 2.8 | G12: 43 | H12: Walk through wax scenes of Lebanese history | I12: High | J12: Year-round | K12: https://www.tripadvisor.com/Attractions-g298264-Activities-Byblos_Mount_Lebanon_Governorate.html | L12: https://www.google.com/maps/search/?api=1&query=Byblos+Wax+Museum%2C+Byblos+city%2C+Lebanon | M12: Weakest-rated museum in the zone; manage expectations. | N12: 2026-09-10
A13: 12 | B13: Byblos | C13: Byblos city | D13: Roman Theater | E13: Heritage - Archaeology | F13: 4 | G13: 8 | H13: See the relocated Roman theatre inside the castle grounds | I13: High | J13: Year-round | K13: https://www.tripadvisor.com/Attractions-g298264-Activities-Byblos_Mount_Lebanon_Governorate.html | L13: https://www.google.com/maps/search/?api=1&query=Roman+Theater%2C+Byblos+city%2C+Lebanon | N13: 2026-09-10
A14: 13 | B14: Byblos | C14: Byblos city | D14: Sultan Abdul Majid Mosque | E14: Heritage - Religious | F14: 4 | G14: 3 | H14: Visit the Ottoman mosque in the old town | I14: Medium | J14: Year-round | K14: https://www.tripadvisor.com/Attractions-g298264-Activities-Byblos_Mount_Lebanon_Governorate.html | L14: https://www.google.com/maps/search/?api=1&query=Sultan+Abdul+Majid+Mosque%2C+Byblos+city%2C+Lebanon | N14: 2026-09-10
A15: 14 | B15: Byblos | C15: Byblos city | D15: Byblos Public Park | E15: Parks - Family | F15: 4.3 | G15: 25 | H15: Green space and a family walk in the town centre | I15: Medium | J15: Year-round | K15: https://www.tripadvisor.com/Attractions-g298264-Activities-Byblos_Mount_Lebanon_Governorate.html | L15: https://www.google.com/maps/search/?api=1&query=Byblos+Public+Park%2C+Byblos+city%2C+Lebanon | N15: 2026-09-10
A16: 15 | B16: Byblos | C16: Byblos city | D16: Ayla Beach | E16: Beach - Water | F16: 3.5 | G16: 2 | H16: Swim and sunbathe on the town beach | I16: Medium | J16: Summer | K16: https://www.tripadvisor.com/Attractions-g298264-Activities-Byblos_Mount_Lebanon_Governorate.html | L16: https://www.google.com/maps/search/?api=1&query=Ayla+Beach%2C+Byblos+city%2C+Lebanon | M16: Seasonal. | N16: 2026-09-10
A17: 16 | B17: Byblos | C17: Mabaj | D17: Mabaj Grotto | E17: Nature - Cave | F17: 5 | G17: 2 | H17: Visit the grotto; guided access advised | I17: Low | J17: Dry season | K17: https://www.tripadvisor.com/Attractions-g298264-Activities-Byblos_Mount_Lebanon_Governorate.html | L17: https://www.google.com/maps/search/?api=1&query=Mabaj+Grotto%2C+Mabaj%2C+Lebanon | M17: Very thin public evidence - verify access locally. | N17: 2026-09-10
A18: 17 | B18: Byblos | C18: Byblos city | D18: Tactick Escape Games | E18: Family - Entertainment | F18: 5 | G18: 11 | H18: Play escape rooms | I18: Medium | J18: Year-round | K18: https://www.tripadvisor.com/Attractions-g298264-Activities-Byblos_Mount_Lebanon_Governorate.html | L18: https://www.google.com/maps/search/?api=1&query=Tactick+Escape+Games%2C+Byblos+city%2C+Lebanon | N18: 2026-09-10
A19: 18 | B19: Byblos | C19: Byblos city | D19: Byblos International Festival | E19: Event - Festival | H19: Attend the summer concert season in the historic port | I19: High | J19: Summer | K19: https://www.byblosfestival.com/ | L19: https://www.google.com/maps/search/?api=1&query=Byblos+International+Festival%2C+Byblos+city%2C+Lebanon | M19: Programme confirmed year by year - check the official site for the 2026 edition. | N19: 2026-09-10
A20: 19 | B20: Byblos | C20: Byblos city | D20: Edde Sands | E20: Beach - Resort | H20: Beach club, pools and seaside dining | I20: Medium | J20: Summer | K20: https://www.myguidebeirut.com/things-to-do/edde-sands | L20: https://www.google.com/maps/search/?api=1&query=Edde+Sands%2C+Byblos+city%2C+Lebanon | M20: Long-running Byblos beach resort. | N20: 2026-09-10
A21: 20 | B21: Byblos | C21: Laqlouq | D21: Laqlouq Ski Resort | E21: Sports - Winter | H21: Ski and snowboard at 1,650-1,920 m across 9 lifts; family and intermediate terrain | I21: High | J21: Winter | K21: https://www.skileb.com/ski-lebanon/resorts/ | L21: https://www.google.com/maps/search/?api=1&query=Laqlouq+Ski+Resort%2C+Laqlouq%2C+Lebanon | M21: Jbeil district's own ski station; gentler than Mzaar. | N21: 2026-09-10
A22: 21 | B22: Jounieh | C22: Jounieh - Harissa | D22: Teleferique (Jounieh to Harissa) | E22: Sports - Cable car | F22: 4.4 | G22: 255 | H22: Ride the gondola from the bay up to the shrine | I22: High | J22: Year-round | K22: https://www.tripadvisor.com/Attractions-g298267-Activities-Jounieh_Mount_Lebanon_Governorate.html | L22: https://www.google.com/maps/search/?api=1&query=Teleferique+%28Jounieh+to+Harissa%29%2C+Jounieh+-+Harissa%2C+Lebanon | M22: The signature experience of the zone; weather-dependent. | N22: 2026-09-10
A23: 22 | B23: Jounieh | C23: Maameltein | D23: Casino du Liban | E23: Entertainment - Casino | F23: 3.5 | G23: 11 | H23: Gaming floors, shows at the Salle des Ambassadeurs, dining | I23: High | J23: Year-round | K23: https://www.tripadvisor.com/Attractions-g298267-Activities-Jounieh_Mount_Lebanon_Governorate.html | L23: https://www.google.com/maps/search/?api=1&query=Casino+du+Liban%2C+Maameltein%2C+Lebanon | M23: Historic 1959 venue on the north side of the bay. | N23: 2026-09-10
A24: 23 | B24: Jounieh | C24: Jounieh bay | D24: Paragliding LESA | E24: Sports - Adventure | F24: 5 | G24: 360 | H24: Tandem paragliding over Jounieh bay | I24: High | J24: Spring to autumn | K24: https://www.tripadvisor.com/Attractions-g298267-Activities-Jounieh_Mount_Lebanon_Governorate.html | L24: https://www.google.com/maps/search/?api=1&query=Paragliding+LESA%2C+Jounieh+bay%2C+Lebanon | M24: Largest review base of any paragliding club here. | N24: 2026-09-10
A25: 24 | B25: Jounieh | C25: Jounieh bay | D25: Paragliding Club Thermique | E25: Sports - Adventure | F25: 5 | G25: 287 | H25: Tandem flights and courses over the bay | I25: High | J25: Spring to autumn | K25: https://www.tripadvisor.com/Attractions-g298267-Activities-Jounieh_Mount_Lebanon_Governorate.html | L25: https://www.google.com/maps/search/?api=1&query=Paragliding+Club+Thermique%2C+Jounieh+bay%2C+Lebanon | N25: 2026-09-10
A26: 25 | B26: Jounieh | C26: Jounieh bay | D26: Thrillseekers | E26: Sports - Adventure | F26: 5 | G26: 64 | H26: Tandem paragliding and adventure packages | I26: High | J26: Spring to autumn | K26: https://www.tripadvisor.com/Attractions-g298267-Activities-Jounieh_Mount_Lebanon_Governorate.html | L26: https://www.google.com/maps/search/?api=1&query=Thrillseekers%2C+Jounieh+bay%2C+Lebanon | N26: 2026-09-10
A27: 26 | B27: Jounieh | C27: Jounieh bay | D27: Paragliding Jounieh | E27: Sports - Adventure | F27: 5 | G27: 50 | H27: Tandem paragliding flights | I27: High | J27: Spring to autumn | K27: https://www.tripadvisor.com/Attractions-g298267-Activities-Jounieh_Mount_Lebanon_Governorate.html | L27: https://www.google.com/maps/search/?api=1&query=Paragliding+Jounieh%2C+Jounieh+bay%2C+Lebanon | M27: Several operators trade under similar names - confirm which one you book. | N27: 2026-09-10
A28: 27 | B28: Jounieh | C28: Jounieh | D28: Gravity Outdoor Advisors | E28: Sports - Gear & guiding | F28: 5 | G28: 29 | H28: Rent outdoor gear, book guided trips | I28: High | J28: Year-round | K28: https://www.tripadvisor.com/Attractions-g298267-Activities-Jounieh_Mount_Lebanon_Governorate.html | L28: https://www.google.com/maps/search/?api=1&query=Gravity+Outdoor+Advisors%2C+Jounieh%2C+Lebanon | N28: 2026-09-10
A29: 28 | B29: Jounieh | C29: Jounieh bay | D29: U-961 Scuba Diving Lebanon | E29: Sports - Diving | F29: 4 | G29: 4 | H29: Dive the bay, including the U-boat wreck site | I29: Medium | J29: Spring to autumn | K29: https://www.tripadvisor.com/Attractions-g298267-Activities-Jounieh_Mount_Lebanon_Governorate.html | L29: https://www.google.com/maps/search/?api=1&query=U-961+Scuba+Diving+Lebanon%2C+Jounieh+bay%2C+Lebanon | N29: 2026-09-10
A30: 29 | B30: Jounieh | C30: Jounieh bay | D30: Octopusteam Diving Club | E30: Sports - Diving | H30: Scuba and snorkelling trips | I30: Medium | J30: Spring to autumn | K30: https://www.tripadvisor.com/Attractions-g298267-Activities-Jounieh_Mount_Lebanon_Governorate.html | L30: https://www.google.com/maps/search/?api=1&query=Octopusteam+Diving+Club%2C+Jounieh+bay%2C+Lebanon | N30: 2026-09-10
A31: 30 | B31: Jounieh | C31: Keserwan mountains | D31: Moon Monkey Adventures | E31: Sports - Climbing | F31: 5 | G31: 3 | H31: Guided climbing and outdoor days | I31: Medium | J31: Spring to autumn | K31: https://www.tripadvisor.com/Attractions-g298267-Activities-Jounieh_Mount_Lebanon_Governorate.html | L31: https://www.google.com/maps/search/?api=1&query=Moon+Monkey+Adventures%2C+Keserwan+mountains%2C+Lebanon | N31: 2026-09-10
A32: 31 | B32: Jounieh | C32: Jeita | D32: Jeita Grotto | E32: Nature - Cave | H32: Walk the upper gallery and ride the boat through the lower river cave | I32: High | J32: Year-round (lower cave closes in high water) | K32: https://www.tripadvisor.com/Attraction_Review-g2624572-d318145-Reviews-Jeita_Grotto-Jitta_Mount_Lebanon_Governorate.html | L32: https://www.google.com/maps/search/?api=1&query=Jeita+Grotto%2C+Jeita%2C+Lebanon | M32: Keserwan's world-famous limestone cave system; lower gallery closes when the river runs high. | N32: 2026-09-10
A33: 32 | B33: Jounieh | C33: Bkerke | D33: Maronite Patriarchate, Bkerke | E33: Heritage - Religious | H33: Visit the seat of the Maronite Church above Jounieh | I33: High | J33: Year-round | K33: https://www.tripadvisor.com/Attractions-g298267-Activities-Jounieh_Mount_Lebanon_Governorate.html | L33: https://www.google.com/maps/search/?api=1&query=Maronite+Patriarchate%2C+Bkerke%2C+Bkerke%2C+Lebanon | N33: 2026-09-10
A34: 33 | B34: Jounieh | C34: Jounieh bay | D34: Jounieh public beaches and beach clubs | E34: Beach - Water | H34: Swim, sunbathe, beach clubs along the bay | I34: Medium | J34: Summer | K34: https://www.tripadvisor.com/Attractions-g298267-Activities-Jounieh_Mount_Lebanon_Governorate.html | L34: https://www.google.com/maps/search/?api=1&query=Jounieh+public+beaches+and+beach+clubs%2C+Jounieh+bay%2C+Lebanon | M34: Quality varies sharply between clubs - check current reviews. | N34: 2026-09-10
A35: 34 | B35: Jounieh | C35: Jounieh | D35: Afkar Creative | E35: Family - Workshops | H35: Paint and pottery studio sessions | I35: Medium | J35: Year-round | K35: https://www.tripadvisor.com/Attractions-g298267-Activities-Jounieh_Mount_Lebanon_Governorate.html | L35: https://www.google.com/maps/search/?api=1&query=Afkar+Creative%2C+Jounieh%2C+Lebanon | N35: 2026-09-10
A36: 35 | B36: Harissa | C36: Harissa | D36: Our Lady of Lebanon Shrine | E36: Heritage - Pilgrimage | H36: Climb the spiral ramp to the bronze statue; visit the modern basilica | I36: High | J36: Year-round | K36: https://www.tripadvisor.com/Attraction_Review-g1598721-d555753-Reviews-The_Shrine_of_Our_Lady_of_Lebanon-Harissa_Mount_Lebanon_Governorate.html | L36: https://www.google.com/maps/search/?api=1&query=Our+Lady+of+Lebanon+Shrine%2C+Harissa%2C+Lebanon | M36: Lebanon's most visited religious site; free entry, busiest on Sundays and in May. | N36: 2026-09-10
A37: 36 | B37: Harissa | C37: Harissa | D37: Saint Paul Basilica | E37: Heritage - Religious | H37: Visit the Melkite Greek Catholic basilica beside the shrine | I37: Medium | J37: Year-round | K37: https://www.tripadvisor.com/Attraction_Review-g1598721-d555753-Reviews-The_Shrine_of_Our_Lady_of_Lebanon-Harissa_Mount_Lebanon_Governorate.html | L37: https://www.google.com/maps/search/?api=1&query=Saint+Paul+Basilica%2C+Harissa%2C+Lebanon | M37: Byzantine-style interior; a short walk from the statue. | N37: 2026-09-10
A38: 37 | B38: Harissa | C38: Harissa | D38: Harissa ridge viewpoints | E38: Nature - Viewpoint | H38: Panoramic views over Jounieh bay, best at sunset | I38: High | J38: Year-round | K38: https://www.tripadvisor.com/Attraction_Review-g1598721-d555753-Reviews-The_Shrine_of_Our_Lady_of_Lebanon-Harissa_Mount_Lebanon_Governorate.html | L38: https://www.google.com/maps/search/?api=1&query=Harissa+ridge+viewpoints%2C+Harissa%2C+Lebanon | M38: Several terraces and cafes share the same view line. | N38: 2026-09-10
A39: 38 | B39: Harissa | C39: Daraoun | D39: Teleferique upper station | E39: Sports - Cable car | F39: 4.4 | G39: 255 | H39: Arrival plaza, food court and shops at the top of the gondola | I39: High | J39: Year-round | K39: https://www.tripadvisor.com/Attractions-g298267-Activities-Jounieh_Mount_Lebanon_Governorate.html | L39: https://www.google.com/maps/search/?api=1&query=Teleferique+upper+station%2C+Daraoun%2C+Lebanon | M39: Same operation as the Jounieh station. | N39: 2026-09-10
A40: 39 | B40: Faraya | C40: Mzaar | D40: Mzaar Kfardebian Ski Resort | E40: Sports - Winter | F40: 4.4 | G40: 137 | H40: Ski and snowboard from 1,830 m to 2,465 m across 18 lifts, up to black runs | I40: High | J40: Winter | K40: https://www.skileb.com/ski-lebanon/resorts/ | L40: https://www.google.com/maps/search/?api=1&query=Mzaar+Kfardebian+Ski+Resort%2C+Mzaar%2C+Lebanon | M40: The largest ski area in the Middle East; summer use for hiking and events. | N40: 2026-09-10
...

Sheet Locality Summary
A1: Area | B1: Exact Locality | C1: Food Records | D1: Activity Records | E1: Research Note
A2: Aqoura | B2: Aaqoura | C2: =COUNTIFS('Food & Drink'!$B$2:$B$259,$A2,'Food & Drink'!$C$2:$C$259,$B2) -> 0 | D2: =COUNTIFS(Activities!$B$2:$B$59,$A2,Activities!$C$2:$C$59,$B2) -> 4 | E2: Counts reflect what is publicly indexed today; on-the-ground checks will find unlisted places, especially in villages.
A3: Aqoura | B3: Aaqoura highlands | C3: =COUNTIFS('Food & Drink'!$B$2:$B$259,$A3,'Food & Drink'!$C$2:$C$259,$B3) -> 1 | D3: =COUNTIFS(Activities!$B$2:$B$59,$A3,Activities!$C$2:$C$59,$B3) -> 1 | E3: Counts reflect what is publicly indexed today; on-the-ground checks will find unlisted places, especially in villages.
A4: Aqoura | B4: Aaqoura village | C4: =COUNTIFS('Food & Drink'!$B$2:$B$259,$A4,'Food & Drink'!$C$2:$C$259,$B4) -> 6 | D4: =COUNTIFS(Activities!$B$2:$B$59,$A4,Activities!$C$2:$C$59,$B4) -> 0 | E4: Counts reflect what is publicly indexed today; on-the-ground checks will find unlisted places, especially in villages.
A5: Aqoura | B5: Adonis valley | C5: =COUNTIFS('Food & Drink'!$B$2:$B$259,$A5,'Food & Drink'!$C$2:$C$259,$B5) -> 0 | D5: =COUNTIFS(Activities!$B$2:$B$59,$A5,Activities!$C$2:$C$59,$B5) -> 1 | E5: Counts reflect what is publicly indexed today; on-the-ground checks will find unlisted places, especially in villages.
A6: Aqoura | B6: Afqa | C6: =COUNTIFS('Food & Drink'!$B$2:$B$259,$A6,'Food & Drink'!$C$2:$C$259,$B6) -> 0 | D6: =COUNTIFS(Activities!$B$2:$B$59,$A6,Activities!$C$2:$C$59,$B6) -> 2 | E6: Counts reflect what is publicly indexed today; on-the-ground checks will find unlisted places, especially in villages.
A7: Byblos | B7: Amchit | C7: =COUNTIFS('Food & Drink'!$B$2:$B$259,$A7,'Food & Drink'!$C$2:$C$259,$B7) -> 14 | D7: =COUNTIFS(Activities!$B$2:$B$59,$A7,Activities!$C$2:$C$59,$B7) -> 0 | E7: Counts reflect what is publicly indexed today; on-the-ground checks will find unlisted places, especially in villages.
A8: Byblos | B8: Amchit seaside road | C8: =COUNTIFS('Food & Drink'!$B$2:$B$259,$A8,'Food & Drink'!$C$2:$C$259,$B8) -> 1 | D8: =COUNTIFS(Activities!$B$2:$B$59,$A8,Activities!$C$2:$C$59,$B8) -> 0 | E8: Counts reflect what is publicly indexed today; on-the-ground checks will find unlisted places, especially in villages.
A9: Byblos | B9: Annaya | C9: =COUNTIFS('Food & Drink'!$B$2:$B$259,$A9,'Food & Drink'!$C$2:$C$259,$B9) -> 1 | D9: =COUNTIFS(Activities!$B$2:$B$59,$A9,Activities!$C$2:$C$59,$B9) -> 1 | E9: Counts reflect what is publicly indexed today; on-the-ground checks will find unlisted places, especially in villages.
A10: Byblos | B10: Byblos Sud | C10: =COUNTIFS('Food & Drink'!$B$2:$B$259,$A10,'Food & Drink'!$C$2:$C$259,$B10) -> 1 | D10: =COUNTIFS(Activities!$B$2:$B$59,$A10,Activities!$C$2:$C$59,$B10) -> 0 | E10: Counts reflect what is publicly indexed today; on-the-ground checks will find unlisted places, especially in villages.
A11: Byblos | B11: Byblos city | C11: =COUNTIFS('Food & Drink'!$B$2:$B$259,$A11,'Food & Drink'!$C$2:$C$259,$B11) -> 48 | D11: =COUNTIFS(Activities!$B$2:$B$59,$A11,Activities!$C$2:$C$59,$B11) -> 16 | E11: Counts reflect what is publicly indexed today; on-the-ground checks will find unlisted places, especially in villages.
A12: Byblos | B12: Byblos city / old port | C12: =COUNTIFS('Food & Drink'!$B$2:$B$259,$A12,'Food & Drink'!$C$2:$C$259,$B12) -> 1 | D12: =COUNTIFS(Activities!$B$2:$B$59,$A12,Activities!$C$2:$C$59,$B12) -> 0 | E12: Counts reflect what is publicly indexed today; on-the-ground checks will find unlisted places, especially in villages.
A13: Byblos | B13: Byblos city / seafront | C13: =COUNTIFS('Food & Drink'!$B$2:$B$259,$A13,'Food & Drink'!$C$2:$C$259,$B13) -> 3 | D13: =COUNTIFS(Activities!$B$2:$B$59,$A13,Activities!$C$2:$C$59,$B13) -> 0 | E13: Counts reflect what is publicly indexed today; on-the-ground checks will find unlisted places, especially in villages.
... A41: Jounieh | B41: Zouk Mosbeh | C41: =COUNTIFS('Food & Drink'!$B$2:$B$259,$A41,'Food & Drink'!$C$2:$C$259,$B41) -> 29 | D41: =COUNTIFS(Activities!$B$2:$B$59,$A41,Activities!$C$2:$C$59,$B41) -> 0 | E41: Counts reflect what is publicly indexed today; on-the-ground checks will find unlisted places, especially in villages.

Sheet Area Definitions
A1: Area | B1: Geographic Interpretation | C1: Included Localities | D1: Excluded / Caution
A2: Jounieh | B2: Jounieh bay city and the continuous coastal strip of southern Keserwan. | C2: Jounieh city, Kaslik, Sarba, Maameltein, Haret Sakher, Zouk Mosbeh, Ghazir, Kfarhbab, Adma | D2: Zouk Mosbeh and Ghazir are separate towns - never label them 'Jounieh city'.
A3: Harissa | B3: The pilgrimage plateau above Jounieh, reached by road or cable car. | C3: Harissa, Daraoun, teleferique upper station | D3: Some platforms file Harissa venues under Jounieh; check the Exact Locality field.
A4: Faraya | B4: Kfardebian municipality, covering the village, Faqra and the Mzaar ski area. | C4: Faraya village, Kfardebian, Faqra, Mzaar | D4: 'Faraya' colloquially covers all of it; administratively the municipality is Kfardebian.
A5: Byblos | B5: Byblos/Jbeil city and its immediate neighbours in Jbeil district. | C5: Byblos city, Mina Jbeil, Byblos Sud, Amchit, Annaya, Hakel, Laqlouq | D5: Annaya and Laqlouq are mountain villages well inland - do not treat them as coastal Byblos.
A6: Aqoura | B6: High Jbeil district: Aaqoura village and the upper Adonis valley. | C6: Aaqoura village, Aaqoura highlands, Afqa, Nahr Ibrahim valley | D6: Winter access is snow-dependent; several sites need a guide or 4WD.

Sheet Method & Sources
A1: Source | B1: URL | C1: Coverage | D1: Use
A2: Tripadvisor - Byblos restaurants | B2: https://www.tripadvisor.com/Restaurants-g298264-Byblos_Mount_Lebanon_Governorate.html | C2: Byblos | D2: Ratings and review counts for the main Byblos dining names.
A3: Tripadvisor - Byblos cafes | B3: https://www.tripadvisor.com/Restaurants-g298264-c8-Byblos_Mount_Lebanon_Governorate.html | C3: Byblos | D3: Coffee-shop ratings.
A4: Tripadvisor - Byblos attractions | B4: https://www.tripadvisor.com/Attractions-g298264-Activities-Byblos_Mount_Lebanon_Governorate.html | C4: Byblos | D4: Ranked attractions with review volume.
A5: Tripadvisor - Jounieh restaurants | B5: https://www.tripadvisor.com/Restaurants-g298267-Jounieh_Mount_Lebanon_Governorate.html | C5: Jounieh, Harissa | D5: Ratings for the top Jounieh-bay tables.
A6: Tripadvisor - Jounieh attractions | B6: https://www.tripadvisor.com/Attractions-g298267-Activities-Jounieh_Mount_Lebanon_Governorate.html | C6: Jounieh | D6: Cable car, casino, paragliding and diving operators.
A7: Tripadvisor - Kfardebian restaurants | B7: https://www.tripadvisor.com/Restaurants-g298268-Kfardebian_Mount_Lebanon_Governorate.html | C7: Faraya | D7: Ratings for Faraya, Faqra and Mzaar restaurants.
A8: Tripadvisor - Kfardebian attractions | B8: https://www.tripadvisor.com/Attractions-g298268-Activities-Kfardebian_Mount_Lebanon_Governorate.html | C8: Faraya | D8: Ski area, Faqra ruins, natural bridge, off-road clubs.
A9: Tripadvisor - El Aaqoura restaurants | B9: https://www.tripadvisor.com/Restaurants-g15023338-El_Aaqoura_Mount_Lebanon_Governorate.html | C9: Aqoura | D9: Confirms how thin the reviewed dining scene is.
A10: Tripadvisor - Our Lady of Lebanon | B10: https://www.tripadvisor.com/Attraction_Review-g1598721-d555753-Reviews-The_Shrine_of_Our_Lady_of_Lebanon-Harissa_Mount_Lebanon_Governorate.html | C10: Harissa | D10: Shrine visitor information.
A11: Tripadvisor - Jeita Grotto | B11: https://www.tripadvisor.com/Attraction_Review-g2624572-d318145-Reviews-Jeita_Grotto-Jitta_Mount_Lebanon_Governorate.html | C11: Keserwan | D11: Cave galleries and seasonal closure of the lower river cave.
A12: WenRayhin - Byblos | B12: https://wenrayhin.com/en/towns/byblos/food_drink | C12: Byblos | D12: Exact-town food and drink listings (OSM / Google Places).
... A26: BAM - LMT stage 13 Faraya/Chabrouh | B26: https://bamleb.com/guide/hiking-trails/lmt-13-faraya-chabrouh-kfardebian | C26: Faraya | D26: Lebanon Mountain Trail routing through Chabrouh.
